Workbook

Sheet 使い方
B1: 事務管理ブック（サンプル入り版）
B2: ※ このファイルの会社名・金額・取引先はすべてサンプルです。実際の運用前に、サンプル行を消してから使ってください。
B4: 色の約束
B5: 黄色のセル | C5: 自分で入力する場所です。
B6: 灰色のセル | C6: 自動で計算される場所です。上書きしないでください（数式が消えます）。
B8: 最初にやること
B9: ① 設定 | C9: 「設定」シートに自社名・住所・インボイス番号・振込先を入れます（見積書・請求書に自動で入ります）。
B10: ② 案件台帳 | C10: 案件を1行ずつ登録します（案件No・案件名・取引先・請負金額）。案件Noは自由な番号でOK（例: 2610-01）。
B11: ③ 見積書 | C11: 案件Noを選ぶと宛名・件名が入ります。明細（工種・品名・数量・単価）を入力。印刷はA3、1ページに収まります。
B12: ④ 予算管理 | C12: 業者に発注したら1件1行で入力。案件ごとの外注費と粗利が「案件台帳」に自動で出ます。
B13: ⑤ 請求書 | C13: 案件Noを選ぶと、請負金額が1行（一式）で入ります。分割請求は「請求割合」を変えます（例: 50%）。
B14: ⑥ 支払管理 | C14: 業者から届いた請求書を入力。支払状況を選ぶと色が変わり、期限切れは赤字になります。
B15: ⑦ 入出金帳 | C15: 入金・出金を1行ずつ入力。残高が自動で出ます。案件Noを選ぶと、その案件の入金済額・未入金額が台帳に出ます。
B16: ⑧ ダッシュボード | C16: 残高・未入金・未払い・月別の入出金・案件別の粗利を一覧で見られます（入力は不要）。
B18: 気をつけること
B19: ・ | C19: 請負金額・見積金額は、必ず本人が最終確認して入力してください（自動では決まりません）。
B20: ・ | C20: 行を並べ替える時は、同じシートの行ごと選んで「データ」タブの並べ替えを使ってください。
B21: ・ | C21: 案件台帳の合計・粗利は、状況が「見積中」「失注」の案件を除いて計算します（受注した案件だけを数えるため）。
B22: ・ | C22: 入出金帳の残高は上から順に計算します。行の途中に空き行を作らないでください。
B23: ・ | C23: 行が足りなくなったら、最終行の1行上を選んで行を挿入し、数式のある行をコピーしてください。
B24: ・ | C24: 他の人に渡す時は「設定」の自社情報を書き換え、サンプルを消してお渡しください（空白版もあります）。
B25: ・ | C25: マクロは使っていません。ExcelでもGoogleスプレッドシートでも開けます。

Sheet ダッシュボード
B1: ダッシュボード（全体の状況）
B2: すべて自動計算です。入力は他のシートで行ってください。
B4: 現在の残高 | C4: 未入金の合計（税込） | D4: 未払いの合計（税込） | E4: 今月が期限の未払い | F4: 期限超過の支払い | G4: 粗利の合計（税抜）
B5: ='入出金帳'!I3 | C5: ='案件台帳'!M3 | D5: =SUMIF('支払管理'!$I$11:$I$210,"未払い",'支払管理'!$G$11:$G$210)+SUMIF('支払管理'!$I$11:$I$210,"問題あり",'支払管理'!$G$11:$G$210) | E5: =SUMIFS('支払管理'!$G$11:$G$210,'支払管理'!$H$11:$H$210,">="&DATE(YEAR(TODAY()),MONTH(TODAY()),1),'支払管理'!$H$11:$H$210,"<"&EDATE(DATE(YEAR(TODAY()),MONTH(TODAY()),1),1),'支払管理'!$I$11:$I$210,"<>支払い済み") | F5: =COUNTIFS('支払管理'!$H$11:$H$210,"<"&TODAY(),'支払管理'!$I$11:$I$210,"<>支払い済み",'支払管理'!$B$11:$B$210,"<>") | G5: ='案件台帳'!J3
B7: ■ 案件の状況別
B8: 状況 | C8: 件数 | D8: 請負金額（税抜）
B9: ='設定'!B19 | C9: =IF(B9="","",COUNTIF('案件台帳'!$E$6:$E$105,B9)) | D9: =IF(B9="","",SUMIF('案件台帳'!$E$6:$E$105,B9,'案件台帳'!$F$6:$F$105))
B10: ='設定'!B20 | C10: =IF(B10="","",COUNTIF('案件台帳'!$E$6:$E$105,B10)) | D10: =IF(B10="","",SUMIF('案件台帳'!$E$6:$E$105,B10,'案件台帳'!$F$6:$F$105))
B11: ='設定'!B21 | C11: =IF(B11="","",COUNTIF('案件台帳'!$E$6:$E$105,B11)) | D11: =IF(B11="","",SUMIF('案件台帳'!$E$6:$E$105,B11,'案件台帳'!$F$6:$F$105))
B12: ='設定'!B22 | C12: =IF(B12="","",COUNTIF('案件台帳'!$E$6:$E$105,B12)) | D12: =IF(B12="","",SUMIF('案件台帳'!$E$6:$E$105,B12,'案件台帳'!$F$6:$F$105))
B13: ='設定'!B23 | C13: =IF(B13="","",COUNTIF('案件台帳'!$E$6:$E$105,B13)) | D13: =IF(B13="","",SUMIF('案件台帳'!$E$6:$E$105,B13,'案件台帳'!$F$6:$F$105))
B14: ='設定'!B24 | C14: =IF(B14="","",COUNTIF('案件台帳'!$E$6:$E$105,B14)) | D14: =IF(B14="","",SUMIF('案件台帳'!$E$6:$E$105,B14,'案件台帳'!$F$6:$F$105))
B16: ■ 月別の入出金（開始月は「設定」で変更）
B17: 月 | C17: 入金 | D17: 出金 | E17: 差引
B18: =EDATE('設定'!$C$14,0) | C18: =SUMIFS('入出金帳'!$G$6:$G$505,'入出金帳'!$A$6:$A$505,">="&B18,'入出金帳'!$A$6:$A$505,"<"&EDATE(B18,1)) | D18: =SUMIFS('入出金帳'!$H$6:$H$505,'入出金帳'!$A$6:$A$505,">="&B18,'入出金帳'!$A$6:$A$505,"<"&EDATE(B18,1)) | E18: =C18-D18
B19: =EDATE('設定'!$C$14,1) | C19: =SUMIFS('入出金帳'!$G$6:$G$505,'入出金帳'!$A$6:$A$505,">="&B19,'入出金帳'!$A$6:$A$505,"<"&EDATE(B19,1)) | D19: =SUMIFS('入出金帳'!$H$6:$H$505,'入出金帳'!$A$6:$A$505,">="&B19,'入出金帳'!$A$6:$A$505,"<"&EDATE(B19,1)) | E19: =C19-D19
B20: =EDATE('設定'!$C$14,2) | C20: =SUMIFS('入出金帳'!$G$6:$G$505,'入出金帳'!$A$6:$A$505,">="&B20,'入出金帳'!$A$6:$A$505,"<"&EDATE(B20,1)) | D20: =SUMIFS('入出金帳'!$H$6:$H$505,'入出金帳'!$A$6:$A$505,">="&B20,'入出金帳'!$A$6:$A$505,"<"&EDATE(B20,1)) | E20: =C20-D20
B21: =EDATE('設定'!$C$14,3) | C21: =SUMIFS('入出金帳'!$G$6:$G$505,'入出金帳'!$A$6:$A$505,">="&B21,'入出金帳'!$A$6:$A$505,"<"&EDATE(B21,1)) | D21: =SUMIFS('入出金帳'!$H$6:$H$505,'入出金帳'!$A$6:$A$505,">="&B21,'入出金帳'!$A$6:$A$505,"<"&EDATE(B21,1)) | E21: =C21-D21
B22: =EDATE('設定'!$C$14,4) | C22: =SUMIFS('入出金帳'!$G$6:$G$505,'入出金帳'!$A$6:$A$505,">="&B22,'入出金帳'!$A$6:$A$505,"<"&EDATE(B22,1)) | D22: =SUMIFS('入出金帳'!$H$6:$H$505,'入出金帳'!$A$6:$A$505,">="&B22,'入出金帳'!$A$6:$A$505,"<"&EDATE(B22,1)) | E22: =C22-D22
B23: =EDATE('設定'!$C$14,5) | C23: =SUMIFS('入出金帳'!$G$6:$G$505,'入出金帳'!$A$6:$A$505,">="&B23,'入出金帳'!$A$6:$A$505,"<"&EDATE(B23,1)) | D23: =SUMIFS('入出金帳'!$H$6:$H$505,'入出金帳'!$A$6:$A$505,">="&B23,'入出金帳'!$A$6:$A$505,"<"&EDATE(B23,1)) | E23: =C23-D23
B24: =EDATE('設定'!$C$14,6) | C24: =SUMIFS('入出金帳'!$G$6:$G$505,'入出金帳'!$A$6:$A$505,">="&B24,'入出金帳'!$A$6:$A$505,"<"&EDATE(B24,1)) | D24: =SUMIFS('入出金帳'!$H$6:$H$505,'入出金帳'!$A$6:$A$505,">="&B24,'入出金帳'!$A$6:$A$505,"<"&EDATE(B24,1)) | E24: =C24-D24
B25: =EDATE('設定'!$C$14,7) | C25: =SUMIFS('入出金帳'!$G$6:$G$505,'入出金帳'!$A$6:$A$505,">="&B25,'入出金帳'!$A$6:$A$505,"<"&EDATE(B25,1)) | D25: =SUMIFS('入出金帳'!$H$6:$H$505,'入出金帳'!$A$6:$A$505,">="&B25,'入出金帳'!$A$6:$A$505,"<"&EDATE(B25,1)) | E25: =C25-D25
B26: =EDATE('設定'!$C$14,8) | C26: =SUMIFS('入出金帳'!$G$6:$G$505,'入出金帳'!$A$6:$A$505,">="&B26,'入出金帳'!$A$6:$A$505,"<"&EDATE(B26,1)) | D26: =SUMIFS('入出金帳'!$H$6:$H$505,'入出金帳'!$A$6:$A$505,">="&B26,'入出金帳'!$A$6:$A$505,"<"&EDATE(B26,1)) | E26: =C26-D26
B27: =EDATE('設定'!$C$14,9) | C27: =SUMIFS('入出金帳'!$G$6:$G$505,'入出金帳'!$A$6:$A$505,">="&B27,'入出金帳'!$A$6:$A$505,"<"&EDATE(B27,1)) | D27: =SUMIFS('入出金帳'!$H$6:$H$505,'入出金帳'!$A$6:$A$505,">="&B27,'入出金帳'!$A$6:$A$505,"<"&EDATE(B27,1)) | E27: =C27-D27
B28: =EDATE('設定'!$C$14,10) | C28: =SUMIFS('入出金帳'!$G$6:$G$505,'入出金帳'!$A$6:$A$505,">="&B28,'入出金帳'!$A$6:$A$505,"<"&EDATE(B28,1)) | D28: =SUMIFS('入出金帳'!$H$6:$H$505,'入出金帳'!$A$6:$A$505,">="&B28,'入出金帳'!$A$6:$A$505,"<"&EDATE(B28,1)) | E28: =C28-D28
B29: =EDATE('設定'!$C$14,11) | C29: =SUMIFS('入出金帳'!$G$6:$G$505,'入出金帳'!$A$6:$A$505,">="&B29,'入出金帳'!$A$6:$A$505,"<"&EDATE(B29,1)) | D29: =SUMIFS('入出金帳'!$H$6:$H$505,'入出金帳'!$A$6:$A$505,">="&B29,'入出金帳'!$A$6:$A$505,"<"&EDATE(B29,1)) | E29: =C29-D29
B30: 合計 | C30: =SUM(C18:C29) | D30: =SUM(D18:D29) | E30: =SUM(E18:E29)
B33: ■ 案件別の収支（台帳の上から15件）
B34: 案件名 | C34: 状況 | D34: 請負金額 | E34: 外注費 | F34: 粗利 | G34: 粗利率 | H34: 未入金額
B35: =IF('案件台帳'!B6="","",'案件台帳'!B6) | C35: =IF('案件台帳'!B6="","",'案件台帳'!E6&"") | D35: =IF('案件台帳'!B6="","",'案件台帳'!F6) | E35: =IF('案件台帳'!B6="","",'案件台帳'!I6) | F35: =IF('案件台帳'!B6="","",'案件台帳'!J6) | G35: =IF('案件台帳'!B6="","",'案件台帳'!K6) | H35: =IF('案件台帳'!B6="","",'案件台帳'!M6)
B36: =IF('案件台帳'!B7="","",'案件台帳'!B7) | C36: =IF('案件台帳'!B7="","",'案件台帳'!E7&"") | D36: =IF('案件台帳'!B7="","",'案件台帳'!F7) | E36: =IF('案件台帳'!B7="","",'案件台帳'!I7) | F36: =IF('案件台帳'!B7="","",'案件台帳'!J7) | G36: =IF('案件台帳'!B7="","",'案件台帳'!K7) | H36: =IF('案件台帳'!B7="","",'案件台帳'!M7)
B37: =IF('案件台帳'!B8="","",'案件台帳'!B8) | C37: =IF('案件台帳'!B8="","",'案件台帳'!E8&"") | D37: =IF('案件台帳'!B8="","",'案件台帳'!F8) | E37: =IF('案件台帳'!B8="","",'案件台帳'!I8) | F37: =IF('案件台帳'!B8="","",'案件台帳'!J8) | G37: =IF('案件台帳'!B8="","",'案件台帳'!K8) | H37: =IF('案件台帳'!B8="","",'案件台帳'!M8)
B38: =IF('案件台帳'!B9="","",'案件台帳'!B9) | C38: =IF('案件台帳'!B9="","",'案件台帳'!E9&"") | D38: =IF('案件台帳'!B9="","",'案件台帳'!F9) | E38: =IF('案件台帳'!B9="","",'案件台帳'!I9) | F38: =IF('案件台帳'!B9="","",'案件台帳'!J9) | G38: =IF('案件台帳'!B9="","",'案件台帳'!K9) | H38: =IF('案件台帳'!B9="","",'案件台帳'!M9)
B39: =IF('案件台帳'!B10="","",'案件台帳'!B10) | C39: =IF('案件台帳'!B10="","",'案件台帳'!E10&"") | D39: =IF('案件台帳'!B10="","",'案件台帳'!F10) | E39: =IF('案件台帳'!B10="","",'案件台帳'!I10) | F39: =IF('案件台帳'!B10="","",'案件台帳'!J10) | G39: =IF('案件台帳'!B10="","",'案件台帳'!K10) | H39: =IF('案件台帳'!B10="","",'案件台帳'!M10)
B40: =IF('案件台帳'!B11="","",'案件台帳'!B11) | C40: =IF('案件台帳'!B11="","",'案件台帳'!E11&"") | D40: =IF('案件台帳'!B11="","",'案件台帳'!F11) | E40: =IF('案件台帳'!B11="","",'案件台帳'!I11) | F40: =IF('案件台帳'!B11="","",'案件台帳'!J11) | G40: =IF('案件台帳'!B11="","",'案件台帳'!K11) | H40: =IF('案件台帳'!B11="","",'案件台帳'!M11)
B41: =IF('案件台帳'!B12="","",'案件台帳'!B12) | C41: =IF('案件台帳'!B12="","",'案件台帳'!E12&"") | D41: =IF('案件台帳'!B12="","",'案件台帳'!F12) | E41: =IF('案件台帳'!B12="","",'案件台帳'!I12) | F41: =IF('案件台帳'!B12="","",'案件台帳'!J12) | G41: =IF('案件台帳'!B12="","",'案件台帳'!K12) | H41: =IF('案件台帳'!B12="","",'案件台帳'!M12)
B42: =IF('案件台帳'!B13="","",'案件台帳'!B13) | C42: =IF('案件台帳'!B13="","",'案件台帳'!E13&"") | D42: =IF('案件台帳'!B13="","",'案件台帳'!F13) | E42: =IF('案件台帳'!B13="","",'案件台帳'!I13) | F42: =IF('案件台帳'!B13="","",'案件台帳'!J13) | G42: =IF('案件台帳'!B13="","",'案件台帳'!K13) | H42: =IF('案件台帳'!B13="","",'案件台帳'!M13)
B43: =IF('案件台帳'!B14="","",'案件台帳'!B14) | C43: =IF('案件台帳'!B14="","",'案件台帳'!E14&"") | D43: =IF('案件台帳'!B14="","",'案件台帳'!F14) | E43: =IF('案件台帳'!B14="","",'案件台帳'!I14) | F43: =IF('案件台帳'!B14="","",'案件台帳'!J14) | G43: =IF('案件台帳'!B14="","",'案件台帳'!K14) | H43: =IF('案件台帳'!B14="","",'案件台帳'!M14)
B44: =IF('案件台帳'!B15="","",'案件台帳'!B15) | C44: =IF('案件台帳'!B15="","",'案件台帳'!E15&"") | D44: =IF('案件台帳'!B15="","",'案件台帳'!F15) | E44: =IF('案件台帳'!B15="","",'案件台帳'!I15) | F44: =IF('案件台帳'!B15="","",'案件台帳'!J15) | G44: =IF('案件台帳'!B15="","",'案件台帳'!K15) | H44: =IF('案件台帳'!B15="","",'案件台帳'!M15)
B45: =IF('案件台帳'!B16="","",'案件台帳'!B16) | C45: =IF('案件台帳'!B16="","",'案件台帳'!E16&"") | D45: =IF('案件台帳'!B16="","",'案件台帳'!F16) | E45: =IF('案件台帳'!B16="","",'案件台帳'!I16) | F45: =IF('案件台帳'!B16="","",'案件台帳'!J16) | G45: =IF('案件台帳'!B16="","",'案件台帳'!K16) | H45: =IF('案件台帳'!B16="","",'案件台帳'!M16)
...

Sheet 設定
A1: 設定（自社情報・リスト）
A2: 黄色のセルを書き換えてください。他のシートに自動で反映されます。
B3: ■ 自社情報・基本設定
B4: 会社名 | C4: 株式会社サンプル工務店
B5: 代表者名 | C5: 代表取締役 山田 太郎
B6: 郵便番号 | C6: 000-0000
B7: 住所 | C7: ○○県○○市サンプル町1-2-3
B8: 電話番号 | C8: 000-0000-0000
B9: インボイス登録番号 | C9: T0000000000000
B10: 振込先 | C10: サンプル銀行 ○○支店 普通 0000000 株式会社サンプル工務店
B11: 消費税率 | C11: 0.1
B12: 支払サイト（請求日から何日後） | C12: 30
B13: 見積の有効期限（何日） | C13: 30
B14: 集計の開始月（ダッシュボード） | C14: 46204
B15: 入出金帳の繰越残高 | C15: 1000000
B17: ■ ドロップダウンの選択肢（増やす・書き換えOK。空き行に追記できます）
B18: 案件の状況 | C18: 工種 | D18: 入出金の科目 | E18: 支払状況（変更しない）
B19: 見積中 | C19: 解体 | D19: 請負代金入金 | E19: 未払い
B20: 受注 | C20: 仮設・足場 | D20: その他入金 | E20: 問題あり
B21: 施工中 | C21: 土工・基礎 | D21: 外注費 | E21: 支払い済み
B22: 完工 | C22: 鉄筋・型枠 | D22: 材料費
B23: 入金済み | C23: 大工・木工 | D23: 交通費（ETC・ガソリン）
B24: 失注 | C24: 内装 | D24: 駐車場
C25: 塗装 | D25: 消耗品
C26: 防水 | D26: 事務所経費
C27: 左官 | D27: 給与・賞与
C28: 電気 | D28: 税金・保険
C29: 給排水・設備 | D29: その他出金
C30: 屋根・板金
C31: 外構
C32: 清掃・廃材処分
C33: 諸経費
C34: その他

Sheet 案件台帳
A1: 案件台帳
A2: 案件を1行ずつ登録します。ここに登録した「案件No」を、他のシートで選びます。 黄＝入力 灰＝自動計算
A3: 合計（見積中・失注は除く） | F3: =SUM(F6:F105)-SUMIF($E$6:$E$105,"見積中",F6:F105)-SUMIF($E$6:$E$105,"失注",F6:F105) | G3: =SUM(G6:G105)-SUMIF($E$6:$E$105,"見積中",G6:G105)-SUMIF($E$6:$E$105,"失注",G6:G105) | H3: =SUM(H6:H105)-SUMIF($E$6:$E$105,"見積中",H6:H105)-SUMIF($E$6:$E$105,"失注",H6:H105) | I3: =SUM(I6:I105)-SUMIF($E$6:$E$105,"見積中",I6:I105)-SUMIF($E$6:$E$105,"失注",I6:I105) | J3: =SUM(J6:J105) | K3: =IF(N(F3)=0,"",J3/F3) | L3: =SUM(L6:L105) | M3: =SUM(M6:M105)
A5: 案件No | B5: 案件名 | C5: 取引先 | D5: 現場住所 | E5: 状況 | F5: 請負金額 （税抜） | G5: 消費税 | H5: 請負金額 （税込） | I5: 外注費計 （税抜） | J5: 粗利 （税抜） | K5: 粗利率 | L5: 入金済額 （税込） | M5: 未入金額 （税込） | N5: 備考
A6: 2610-01 | B6: サンプルマンション 外壁改修工事 | C6: サンプル不動産株式会社 | D6: ○○県○○市サンプル町1-1 | E6: 施工中 | F6: 8000000 | G6: =IF(F6="","",ROUND(F6*'設定'!$C$11,0)) | H6: =IF(F6="","",F6+G6) | I6: =IF(A6="","",SUMPRODUCT(('予算管理'!$A$6:$A$205=A6)*1,'予算管理'!$E$6:$E$205)) | J6: =IF(OR(A6="",F6="",E6="見積中",E6="失注"),"",F6-I6) | K6: =IF(OR(J6="",N(F6)=0),"",J6/F6) | L6: =IF(A6="","",SUMPRODUCT(('入出金帳'!$B$6:$B$505=A6)*1,'入出金帳'!$G$6:$G$505)) | M6: =IF(OR(A6="",H6="",E6="見積中",E6="失注"),"",H6-L6)
A7: 2610-02 | B7: サンプル店舗 内装工事 | C7: サンプル商事株式会社 | D7: ○○県○○市サンプル町2-2 | E7: 受注 | F7: 3500000 | G7: =IF(F7="","",ROUND(F7*'設定'!$C$11,0)) | H7: =IF(F7="","",F7+G7) | I7: =IF(A7="","",SUMPRODUCT(('予算管理'!$A$6:$A$205=A7)*1,'予算管理'!$E$6:$E$205)) | J7: =IF(OR(A7="",F7="",E7="見積中",E7="失注"),"",F7-I7) | K7: =IF(OR(J7="",N(F7)=0),"",J7/F7) | L7: =IF(A7="","",SUMPRODUCT(('入出金帳'!$B$6:$B$505=A7)*1,'入出金帳'!$G$6:$G$505)) | M7: =IF(OR(A7="",H7="",E7="見積中",E7="失注"),"",H7-L7)
A8: 2609-03 | B8: サンプル邸 屋根防水工事 | C8: 個人（サンプル様） | D8: ○○県○○市サンプル町3-3 | E8: 完工 | F8: 1200000 | G8: =IF(F8="","",ROUND(F8*'設定'!$C$11,0)) | H8: =IF(F8="","",F8+G8) | I8: =IF(A8="","",SUMPRODUCT(('予算管理'!$A$6:$A$205=A8)*1,'予算管理'!$E$6:$E$205)) | J8: =IF(OR(A8="",F8="",E8="見積中",E8="失注"),"",F8-I8) | K8: =IF(OR(J8="",N(F8)=0),"",J8/F8) | L8: =IF(A8="","",SUMPRODUCT(('入出金帳'!$B$6:$B$505=A8)*1,'入出金帳'!$G$6:$G$505)) | M8: =IF(OR(A8="",H8="",E8="見積中",E8="失注"),"",H8-L8)
A9: 2610-04 | B9: サンプルビル 解体工事 | C9: サンプル開発株式会社 | D9: ○○県○○市サンプル町4-4 | E9: 見積中 | F9: 2400000 | G9: =IF(F9="","",ROUND(F9*'設定'!$C$11,0)) | H9: =IF(F9="","",F9+G9) | I9: =IF(A9="","",SUMPRODUCT(('予算管理'!$A$6:$A$205=A9)*1,'予算管理'!$E$6:$E$205)) | J9: =IF(OR(A9="",F9="",E9="見積中",E9="失注"),"",F9-I9) | K9: =IF(OR(J9="",N(F9)=0),"",J9/F9) | L9: =IF(A9="","",SUMPRODUCT(('入出金帳'!$B$6:$B$505=A9)*1,'入出金帳'!$G$6:$G$505)) | M9: =IF(OR(A9="",H9="",E9="見積中",E9="失注"),"",H9-L9)
G10: =IF(F10="","",ROUND(F10*'設定'!$C$11,0)) | H10: =IF(F10="","",F10+G10) | I10: =IF(A10="","",SUMPRODUCT(('予算管理'!$A$6:$A$205=A10)*1,'予算管理'!$E$6:$E$205)) | J10: =IF(OR(A10="",F10="",E10="見積中",E10="失注"),"",F10-I10) | K10: =IF(OR(J10="",N(F10)=0),"",J10/F10) | L10: =IF(A10="","",SUMPRODUCT(('入出金帳'!$B$6:$B$505=A10)*1,'入出金帳'!$G$6:$G$505)) | M10: =IF(OR(A10="",H10="",E10="見積中",E10="失注"),"",H10-L10)
G11: =IF(F11="","",ROUND(F11*'設定'!$C$11,0)) | H11: =IF(F11="","",F11+G11) | I11: =IF(A11="","",SUMPRODUCT(('予算管理'!$A$6:$A$205=A11)*1,'予算管理'!$E$6:$E$205)) | J11: =IF(OR(A11="",F11="",E11="見積中",E11="失注"),"",F11-I11) | K11: =IF(OR(J11="",N(F11)=0),"",J11/F11) | L11: =IF(A11="","",SUMPRODUCT(('入出金帳'!$B$6:$B$505=A11)*1,'入出金帳'!$G$6:$G$505)) | M11: =IF(OR(A11="",H11="",E11="見積中",E11="失注"),"",H11-L11)
G12: =IF(F12="","",ROUND(F12*'設定'!$C$11,0)) | H12: =IF(F12="","",F12+G12) | I12: =IF(A12="","",SUMPRODUCT(('予算管理'!$A$6:$A$205=A12)*1,'予算管理'!$E$6:$E$205)) | J12: =IF(OR(A12="",F12="",E12="見積中",E12="失注"),"",F12-I12) | K12: =IF(OR(J12="",N(F12)=0),"",J12/F12) | L12: =IF(A12="","",SUMPRODUCT(('入出金帳'!$B$6:$B$505=A12)*1,'入出金帳'!$G$6:$G$505)) | M12: =IF(OR(A12="",H12="",E12="見積中",E12="失注"),"",H12-L12)
G13: =IF(F13="","",ROUND(F13*'設定'!$C$11,0)) | H13: =IF(F13="","",F13+G13) | I13: =IF(A13="","",SUMPRODUCT(('予算管理'!$A$6:$A$205=A13)*1,'予算管理'!$E$6:$E$205)) | J13: =IF(OR(A13="",F13="",E13="見積中",E13="失注"),"",F13-I13) | K13: =IF(OR(J13="",N(F13)=0),"",J13/F13) | L13: =IF(A13="","",SUMPRODUCT(('入出金帳'!$B$6:$B$505=A13)*1,'入出金帳'!$G$6:$G$505)) | M13: =IF(OR(A13="",H13="",E13="見積中",E13="失注"),"",H13-L13)
G14: =IF(F14="","",ROUND(F14*'設定'!$C$11,0)) | H14: =IF(F14="","",F14+G14) | I14: =IF(A14="","",SUMPRODUCT(('予算管理'!$A$6:$A$205=A14)*1,'予算管理'!$E$6:$E$205)) | J14: =IF(OR(A14="",F14="",E14="見積中",E14="失注"),"",F14-I14) | K14: =IF(OR(J14="",N(F14)=0),"",J14/F14) | L14: =IF(A14="","",SUMPRODUCT(('入出金帳'!$B$6:$B$505=A14)*1,'入出金帳'!$G$6:$G$505)) | M14: =IF(OR(A14="",H14="",E14="見積中",E14="失注"),"",H14-L14)
G15: =IF(F15="","",ROUND(F15*'設定'!$C$11,0)) | H15: =IF(F15="","",F15+G15) | I15: =IF(A15="","",SUMPRODUCT(('予算管理'!$A$6:$A$205=A15)*1,'予算管理'!$E$6:$E$205)) | J15: =IF(OR(A15="",F15="",E15="見積中",E15="失注"),"",F15-I15) | K15: =IF(OR(J15="",N(F15)=0),"",J15/F15) | L15: =IF(A15="","",SUMPRODUCT(('入出金帳'!$B$6:$B$505=A15)*1,'入出金帳'!$G$6:$G$505)) | M15: =IF(OR(A15="",H15="",E15="見積中",E15="失注"),"",H15-L15)
G16: =IF(F16="","",ROUND(F16*'設定'!$C$11,0)) | H16: =IF(F16="","",F16+G16) | I16: =IF(A16="","",SUMPRODUCT(('予算管理'!$A$6:$A$205=A16)*1,'予算管理'!$E$6:$E$205)) | J16: =IF(OR(A16="",F16="",E16="見積中",E16="失注"),"",F16-I16) | K16: =IF(OR(J16="",N(F16)=0),"",J16/F16) | L16: =IF(A16="","",SUMPRODUCT(('入出金帳'!$B$6:$B$505=A16)*1,'入出金帳'!$G$6:$G$505)) | M16: =IF(OR(A16="",H16="",E16="見積中",E16="失注"),"",H16-L16)
G17: =IF(F17="","",ROUND(F17*'設定'!$C$11,0)) | H17: =IF(F17="","",F17+G17) | I17: =IF(A17="","",SUMPRODUCT(('予算管理'!$A$6:$A$205=A17)*1,'予算管理'!$E$6:$E$205)) | J17: =IF(OR(A17="",F17="",E17="見積中",E17="失注"),"",F17-I17) | K17: =IF(OR(J17="",N(F17)=0),"",J17/F17) | L17: =IF(A17="","",SUMPRODUCT(('入出金帳'!$B$6:$B$505=A17)*1,'入出金帳'!$G$6:$G$505)) | M17: =IF(OR(A17="",H17="",E17="見積中",E17="失注"),"",H17-L17)
G18: =IF(F18="","",ROUND(F18*'設定'!$C$11,0)) | H18: =IF(F18="","",F18+G18) | I18: =IF(A18="","",SUMPRODUCT(('予算管理'!$A$6:$A$205=A18)*1,'予算管理'!$E$6:$E$205)) | J18: =IF(OR(A18="",F18="",E18="見積中",E18="失注"),"",F18-I18) | K18: =IF(OR(J18="",N(F18)=0),"",J18/F18) | L18: =IF(A18="","",SUMPRODUCT(('入出金帳'!$B$6:$B$505=A18)*1,'入出金帳'!$G$6:$G$505)) | M18: =IF(OR(A18="",H18="",E18="見積中",E18="失注"),"",H18-L18)
G19: =IF(F19="","",ROUND(F19*'設定'!$C$11,0)) | H19: =IF(F19="","",F19+G19) | I19: =IF(A19="","",SUMPRODUCT(('予算管理'!$A$6:$A$205=A19)*1,'予算管理'!$E$6:$E$205)) | J19: =IF(OR(A19="",F19="",E19="見積中",E19="失注"),"",F19-I19) | K19: =IF(OR(J19="",N(F19)=0),"",J19/F19) | L19: =IF(A19="","",SUMPRODUCT(('入出金帳'!$B$6:$B$505=A19)*1,'入出金帳'!$G$6:$G$505)) | M19: =IF(OR(A19="",H19="",E19="見積中",E19="失注"),"",H19-L19)
G20: =IF(F20="","",ROUND(F20*'設定'!$C$11,0)) | H20: =IF(F20="","",F20+G20) | I20: =IF(A20="","",SUMPRODUCT(('予算管理'!$A$6:$A$205=A20)*1,'予算管理'!$E$6:$E$205)) | J20: =IF(OR(A20="",F20="",E20="見積中",E20="失注"),"",F20-I20) | K20: =IF(OR(J20="",N(F20)=0),"",J20/F20) | L20: =IF(A20="","",SUMPRODUCT(('入出金帳'!$B$6:$B$505=A20)*1,'入出金帳'!$G$6:$G$505)) | M20: =IF(OR(A20="",H20="",E20="見積中",E20="失注"),"",H20-L20)
G21: =IF(F21="","",ROUND(F21*'設定'!$C$11,0)) | H21: =IF(F21="","",F21+G21) | I21: =IF(A21="","",SUMPRODUCT(('予算管理'!$A$6:$A$205=A21)*1,'予算管理'!$E$6:$E$205)) | J21: =IF(OR(A21="",F21="",E21="見積中",E21="失注"),"",F21-I21) | K21: =IF(OR(J21="",N(F21)=0),"",J21/F21) | L21: =IF(A21="","",SUMPRODUCT(('入出金帳'!$B$6:$B$505=A21)*1,'入出金帳'!$G$6:$G$505)) | M21: =IF(OR(A21="",H21="",E21="見積中",E21="失注"),"",H21-L21)
... G105: =IF(F105="","",ROUND(F105*'設定'!$C$11,0)) | H105: =IF(F105="","",F105+G105) | I105: =IF(A105="","",SUMPRODUCT(('予算管理'!$A$6:$A$205=A105)*1,'予算管理'!$E$6:$E$205)) | J105: =IF(OR(A105="",F105="",E105="見積中",E105="失注"),"",F105-I105) | K105: =IF(OR(J105="",N(F105)=0),"",J105/F105) | L105: =IF(A105="","",SUMPRODUCT(('入出金帳'!$B$6:$B$505=A105)*1,'入出金帳'!$G$6:$G$505)) | M105: =IF(OR(A105="",H105="",E105="見積中",E105="失注"),"",H105-L105)

Sheet 見積書
A1: 御 見 積 書
A3: 案件No | B3: 2610-02 | F3: 見積番号 | G3: =IF(B3="","",B3&"-E")
A4: 宛名 | B4: =IF(B3="","",IF(B3="","",IFERROR(INDEX('案件台帳'!$C$6:$C$105,MATCH(B3,'案件台帳'!$A$6:$A$105,0)),""))&" 御中") | F4: 見積日 | G4: 46296
A5: 件名 | B5: =IF(B3="","",IFERROR(INDEX('案件台帳'!$B$6:$B$105,MATCH(B3,'案件台帳'!$A$6:$A$105,0)),"")) | F5: 有効期限 | G5: =IF(G4="","",G4+'設定'!$C$13)
A6: 現場 | B6: =IF(B3="","",IFERROR(INDEX('案件台帳'!$D$6:$D$105,MATCH(B3,'案件台帳'!$A$6:$A$105,0)),""))
A8: お見積金額（税込） | C8: =IF(G45=0,"",G47) | F8: ='設定'!C4
F9: =IF('設定'!C6="","","〒"&'設定'!C6&" ")&'設定'!C7
F10: =IF('設定'!C8="","","TEL "&'設定'!C8)
F11: =IF('設定'!C9="","","登録番号 "&'設定'!C9)
F12: ='設定'!C5
A14: No | B14: 工種 | C14: 品名・仕様 | D14: 数量 | E14: 単位 | F14: 単価 | G14: 金額 | H14: 備考
A15: =IF(C15="","",1) | B15: 解体 | C15: 既存内装解体・処分 | D15: 1 | E15: 式 | F15: 350000 | G15: =IF(OR(D15="",F15=""),"",ROUND(D15*F15,0))
A16: =IF(C16="","",2) | B16: 内装 | C16: 軽量鉄骨下地・ボード張り | D16: 85 | E16: ㎡ | F16: 6500 | G16: =IF(OR(D16="",F16=""),"",ROUND(D16*F16,0))
A17: =IF(C17="","",3) | B17: 内装 | C17: クロス張り | D17: 210 | E17: ㎡ | F17: 1800 | G17: =IF(OR(D17="",F17=""),"",ROUND(D17*F17,0))
A18: =IF(C18="","",4) | B18: 内装 | C18: 床 長尺シート張り | D18: 60 | E18: ㎡ | F18: 5500 | G18: =IF(OR(D18="",F18=""),"",ROUND(D18*F18,0))
A19: =IF(C19="","",5) | B19: 電気 | C19: 照明・コンセント工事 | D19: 1 | E19: 式 | F19: 780000 | G19: =IF(OR(D19="",F19=""),"",ROUND(D19*F19,0))
A20: =IF(C20="","",6) | B20: 諸経費 | C20: 現場管理費・諸経費 | D20: 1 | E20: 式 | F20: 1109500 | G20: =IF(OR(D20="",F20=""),"",ROUND(D20*F20,0))
A21: =IF(C21="","",7) | G21: =IF(OR(D21="",F21=""),"",ROUND(D21*F21,0))
A22: =IF(C22="","",8) | G22: =IF(OR(D22="",F22=""),"",ROUND(D22*F22,0))
A23: =IF(C23="","",9) | G23: =IF(OR(D23="",F23=""),"",ROUND(D23*F23,0))
A24: =IF(C24="","",10) | G24: =IF(OR(D24="",F24=""),"",ROUND(D24*F24,0))
A25: =IF(C25="","",11) | G25: =IF(OR(D25="",F25=""),"",ROUND(D25*F25,0))
A26: =IF(C26="","",12) | G26: =IF(OR(D26="",F26=""),"",ROUND(D26*F26,0))
A27: =IF(C27="","",13) | G27: =IF(OR(D27="",F27=""),"",ROUND(D27*F27,0))
A28: =IF(C28="","",14) | G28: =IF(OR(D28="",F28=""),"",ROUND(D28*F28,0))
A29: =IF(C29="","",15) | G29: =IF(OR(D29="",F29=""),"",ROUND(D29*F29,0))
A30: =IF(C30="","",16) | G30: =IF(OR(D30="",F30=""),"",ROUND(D30*F30,0))
A31: =IF(C31="","",17) | G31: =IF(OR(D31="",F31=""),"",ROUND(D31*F31,0))
A32: =IF(C32="","",18) | G32: =IF(OR(D32="",F32=""),"",ROUND(D32*F32,0))
A33: =IF(C33="","",19) | G33: =IF(OR(D33="",F33=""),"",ROUND(D33*F33,0))
A34: =IF(C34="","",20) | G34: =IF(OR(D34="",F34=""),"",ROUND(D34*F34,0))
A35: =IF(C35="","",21) | G35: =IF(OR(D35="",F35=""),"",ROUND(D35*F35,0))
A36: =IF(C36="","",22) | G36: =IF(OR(D36="",F36=""),"",ROUND(D36*F36,0))
A37: =IF(C37="","",23) | G37: =IF(OR(D37="",F37=""),"",ROUND(D37*F37,0))
A38: =IF(C38="","",24) | G38: =IF(OR(D38="",F38=""),"",ROUND(D38*F38,0))
A39: =IF(C39="","",25) | G39: =IF(OR(D39="",F39=""),"",ROUND(D39*F39,0))
A40: =IF(C40="","",26) | G40: =IF(OR(D40="",F40=""),"",ROUND(D40*F40,0))
A41: =IF(C41="","",27) | G41: =IF(OR(D41="",F41=""),"",ROUND(D41*F41,0))
A42: =IF(C42="","",28) | G42: =IF(OR(D42="",F42=""),"",ROUND(D42*F42,0))
A43: =IF(C43="","",29) | G43: =IF(OR(D43="",F43=""),"",ROUND(D43*F43,0))
...

Sheet 予算管理
A1: 予算管理（外注・発注の一覧）
A2: 業者への発注を1件1行で入力します。案件ごとの外注費・粗利は「案件台帳」に自動集計されます。見積のある項目だけ入力してください。
D3: 合計 | E3: =SUM(E6:E205) | F3: =SUM(F6:F205)
A5: 案件No | B5: 案件名 | C5: 工種 | D5: 業者名 | E5: 発注金額 （税抜） | F5: 発注金額 （税込） | G5: 発注日 | H5: 備考
A6: 2610-01 | B6: =IF(A6="","",IFERROR(INDEX('案件台帳'!$B$6:$B$105,MATCH(A6,'案件台帳'!$A$6:$A$105,0)),"")) | C6: 仮設・足場 | D6: サンプル足場工業 | E6: 1200000 | F6: =IF(E6="","",ROUND(E6*(1+'設定'!$C$11),0)) | G6: 46285
A7: 2610-01 | B7: =IF(A7="","",IFERROR(INDEX('案件台帳'!$B$6:$B$105,MATCH(A7,'案件台帳'!$A$6:$A$105,0)),"")) | C7: 塗装 | D7: サンプル塗装店 | E7: 2800000 | F7: =IF(E7="","",ROUND(E7*(1+'設定'!$C$11),0)) | G7: 46290
A8: 2610-01 | B8: =IF(A8="","",IFERROR(INDEX('案件台帳'!$B$6:$B$105,MATCH(A8,'案件台帳'!$A$6:$A$105,0)),"")) | C8: 防水 | D8: サンプル防水工業 | E8: 900000 | F8: =IF(E8="","",ROUND(E8*(1+'設定'!$C$11),0)) | G8: 46296
A9: 2610-02 | B9: =IF(A9="","",IFERROR(INDEX('案件台帳'!$B$6:$B$105,MATCH(A9,'案件台帳'!$A$6:$A$105,0)),"")) | C9: 内装 | D9: サンプル内装 | E9: 1300000 | F9: =IF(E9="","",ROUND(E9*(1+'設定'!$C$11),0)) | G9: 46300
A10: 2610-02 | B10: =IF(A10="","",IFERROR(INDEX('案件台帳'!$B$6:$B$105,MATCH(A10,'案件台帳'!$A$6:$A$105,0)),"")) | C10: 電気 | D10: サンプル電設 | E10: 400000 | F10: =IF(E10="","",ROUND(E10*(1+'設定'!$C$11),0)) | G10: 46303
A11: 2609-03 | B11: =IF(A11="","",IFERROR(INDEX('案件台帳'!$B$6:$B$105,MATCH(A11,'案件台帳'!$A$6:$A$105,0)),"")) | C11: 防水 | D11: サンプル防水工業 | E11: 500000 | F11: =IF(E11="","",ROUND(E11*(1+'設定'!$C$11),0)) | G11: 46266
A12: 2609-03 | B12: =IF(A12="","",IFERROR(INDEX('案件台帳'!$B$6:$B$105,MATCH(A12,'案件台帳'!$A$6:$A$105,0)),"")) | C12: 屋根・板金 | D12: サンプル板金 | E12: 300000 | F12: =IF(E12="","",ROUND(E12*(1+'設定'!$C$11),0)) | G12: 46268
B13: =IF(A13="","",IFERROR(INDEX('案件台帳'!$B$6:$B$105,MATCH(A13,'案件台帳'!$A$6:$A$105,0)),"")) | F13: =IF(E13="","",ROUND(E13*(1+'設定'!$C$11),0))
B14: =IF(A14="","",IFERROR(INDEX('案件台帳'!$B$6:$B$105,MATCH(A14,'案件台帳'!$A$6:$A$105,0)),"")) | F14: =IF(E14="","",ROUND(E14*(1+'設定'!$C$11),0))
B15: =IF(A15="","",IFERROR(INDEX('案件台帳'!$B$6:$B$105,MATCH(A15,'案件台帳'!$A$6:$A$105,0)),"")) | F15: =IF(E15="","",ROUND(E15*(1+'設定'!$C$11),0))
B16: =IF(A16="","",IFERROR(INDEX('案件台帳'!$B$6:$B$105,MATCH(A16,'案件台帳'!$A$6:$A$105,0)),"")) | F16: =IF(E16="","",ROUND(E16*(1+'設定'!$C$11),0))
B17: =IF(A17="","",IFERROR(INDEX('案件台帳'!$B$6:$B$105,MATCH(A17,'案件台帳'!$A$6:$A$105,0)),"")) | F17: =IF(E17="","",ROUND(E17*(1+'設定'!$C$11),0))
B18: =IF(A18="","",IFERROR(INDEX('案件台帳'!$B$6:$B$105,MATCH(A18,'案件台帳'!$A$6:$A$105,0)),"")) | F18: =IF(E18="","",ROUND(E18*(1+'設定'!$C$11),0))
B19: =IF(A19="","",IFERROR(INDEX('案件台帳'!$B$6:$B$105,MATCH(A19,'案件台帳'!$A$6:$A$105,0)),"")) | F19: =IF(E19="","",ROUND(E19*(1+'設定'!$C$11),0))
B20: =IF(A20="","",IFERROR(INDEX('案件台帳'!$B$6:$B$105,MATCH(A20,'案件台帳'!$A$6:$A$105,0)),"")) | F20: =IF(E20="","",ROUND(E20*(1+'設定'!$C$11),0))
B21: =IF(A21="","",IFERROR(INDEX('案件台帳'!$B$6:$B$105,MATCH(A21,'案件台帳'!$A$6:$A$105,0)),"")) | F21: =IF(E21="","",ROUND(E21*(1+'設定'!$C$11),0))
B22: =IF(A22="","",IFERROR(INDEX('案件台帳'!$B$6:$B$105,MATCH(A22,'案件台帳'!$A$6:$A$105,0)),"")) | F22: =IF(E22="","",ROUND(E22*(1+'設定'!$C$11),0))
B23: =IF(A23="","",IFERROR(INDEX('案件台帳'!$B$6:$B$105,MATCH(A23,'案件台帳'!$A$6:$A$105,0)),"")) | F23: =IF(E23="","",ROUND(E23*(1+'設定'!$C$11),0))
B24: =IF(A24="","",IFERROR(INDEX('案件台帳'!$B$6:$B$105,MATCH(A24,'案件台帳'!$A$6:$A$105,0)),"")) | F24: =IF(E24="","",ROUND(E24*(1+'設定'!$C$11),0))
... B205: =IF(A205="","",IFERROR(INDEX('案件台帳'!$B$6:$B$105,MATCH(A205,'案件台帳'!$A$6:$A$105,0)),"")) | F205: =IF(E205="","",ROUND(E205*(1+'設定'!$C$11),0))

Sheet 請求書
A1: 請 求 書
A3: 案件No | B3: 2609-03 | E3: 請求書番号 | F3: =IF(OR(B3="",F4=""),"",B3&"-"&TEXT(F4,"yymmdd"))
A4: 宛名 | B4: =IF(B3="","",IF(B3="","",IFERROR(INDEX('案件台帳'!$C$6:$C$105,MATCH(B3,'案件台帳'!$A$6:$A$105,0)),""))&" 御中") | E4: 請求日 | F4: 46295
A5: 件名 | B5: =IF(B3="","",IFERROR(INDEX('案件台帳'!$B$6:$B$105,MATCH(B3,'案件台帳'!$A$6:$A$105,0)),"")) | E5: お支払期限 | F5: =IF(F4="","",F4+'設定'!$C$12)
A6: 現場 | B6: =IF(B3="","",IFERROR(INDEX('案件台帳'!$D$6:$D$105,MATCH(B3,'案件台帳'!$A$6:$A$105,0)),"")) | E6: 請求割合 | F6: 1
A8: ご請求金額（税込） | C8: =IF(F19="","",F19) | E8: ='設定'!C4
E9: =IF('設定'!C6="","","〒"&'設定'!C6&" ")&'設定'!C7
E10: =IF('設定'!C8="","","TEL "&'設定'!C8)
E11: =IF('設定'!C9="","","登録番号 "&'設定'!C9)
E12: ='設定'!C5
A14: 品名 | C14: 数量 | D14: 単位 | E14: 単価 | F14: 金額
A15: =IF(B5="","",B5&" 一式") | C15: =IF(B3="","",1) | D15: =IF(B3="","","式") | E15: =IF(B3="","",ROUND(IFERROR(INDEX('案件台帳'!$F$6:$F$105,MATCH(B3,'案件台帳'!$A$6:$A$105,0)),0)*F6,0)) | F15: =IF(E15="","",E15)
A17: 小計（税抜） | F17: =N(F15)
A18: 消費税 | F18: =ROUND(F17*'設定'!$C$11,0)
A19: 合計（税込） | F19: =IF(B3="","",F17+F18)
A21: お振込先 | B21: ='設定'!C10
A23: 備考 | B23: お振込手数料はご負担をお願いいたします。

Sheet 支払管理
A1: 支払管理（業者への支払い）
A2: 業者から届いた請求書を1枚1行で入力。支払状況を選ぶと行の色が変わります。期限を過ぎた未払いは赤字になります。
B4: 支払状況 | C4: 件数 | D4: 金額
B5: 未払い | C5: =COUNTIF($I$11:$I$210,B5) | D5: =SUMIF($I$11:$I$210,B5,$G$11:$G$210)
B6: 問題あり | C6: =COUNTIF($I$11:$I$210,B6) | D6: =SUMIF($I$11:$I$210,B6,$G$11:$G$210)
B7: 支払い済み | C7: =COUNTIF($I$11:$I$210,B7) | D7: =SUMIF($I$11:$I$210,B7,$G$11:$G$210)
B8: 合計 | C8: =SUM(C5:C7) | D8: =SUM(D5:D7)
A10: No | B10: 支払先（業者名） | C10: 案件No | D10: 案件名 | E10: 請求書番号 | F10: 請求日 | G10: 請求金額 （税込） | H10: 支払期限 | I10: 支払状況 | J10: 支払日 | K10: 備考 | L10: 期限まで （日）
A11: =IF(B11="","",ROW()-10) | B11: サンプル足場工業 | C11: 2610-01 | D11: =IF(C11="","",IFERROR(INDEX('案件台帳'!$B$6:$B$105,MATCH(C11,'案件台帳'!$A$6:$A$105,0)),"")) | E11: A-101 | F11: 46295 | G11: 1320000 | H11: 46326 | I11: 未払い | L11: =IF(OR(H11="",I11="支払い済み",B11=""),"",H11-TODAY())
A12: =IF(B12="","",ROW()-10) | B12: サンプル塗装店 | C12: 2610-01 | D12: =IF(C12="","",IFERROR(INDEX('案件台帳'!$B$6:$B$105,MATCH(C12,'案件台帳'!$A$6:$A$105,0)),"")) | E12: S-55 | F12: 46295 | G12: 3080000 | H12: 46326 | I12: 未払い | L12: =IF(OR(H12="",I12="支払い済み",B12=""),"",H12-TODAY())
A13: =IF(B13="","",ROW()-10) | B13: サンプル防水工業 | C13: 2609-03 | D13: =IF(C13="","",IFERROR(INDEX('案件台帳'!$B$6:$B$105,MATCH(C13,'案件台帳'!$A$6:$A$105,0)),"")) | E13: B-20 | F13: 46295 | G13: 550000 | H13: 46305 | I13: 未払い | L13: =IF(OR(H13="",I13="支払い済み",B13=""),"",H13-TODAY())
A14: =IF(B14="","",ROW()-10) | B14: サンプル板金 | C14: 2609-03 | D14: =IF(C14="","",IFERROR(INDEX('案件台帳'!$B$6:$B$105,MATCH(C14,'案件台帳'!$A$6:$A$105,0)),"")) | E14: K-8 | F14: 46295 | G14: 330000 | H14: 46305 | I14: 支払い済み | J14: 46304 | L14: =IF(OR(H14="",I14="支払い済み",B14=""),"",H14-TODAY())
A15: =IF(B15="","",ROW()-10) | B15: サンプル内装 | C15: 2610-02 | D15: =IF(C15="","",IFERROR(INDEX('案件台帳'!$B$6:$B$105,MATCH(C15,'案件台帳'!$A$6:$A$105,0)),"")) | E15: N-3 | F15: 46305 | G15: 1430000 | H15: 46356 | I15: 問題あり | L15: =IF(OR(H15="",I15="支払い済み",B15=""),"",H15-TODAY())
A16: =IF(B16="","",ROW()-10) | D16: =IF(C16="","",IFERROR(INDEX('案件台帳'!$B$6:$B$105,MATCH(C16,'案件台帳'!$A$6:$A$105,0)),"")) | L16: =IF(OR(H16="",I16="支払い済み",B16=""),"",H16-TODAY())
A17: =IF(B17="","",ROW()-10) | D17: =IF(C17="","",IFERROR(INDEX('案件台帳'!$B$6:$B$105,MATCH(C17,'案件台帳'!$A$6:$A$105,0)),"")) | L17: =IF(OR(H17="",I17="支払い済み",B17=""),"",H17-TODAY())
A18: =IF(B18="","",ROW()-10) | D18: =IF(C18="","",IFERROR(INDEX('案件台帳'!$B$6:$B$105,MATCH(C18,'案件台帳'!$A$6:$A$105,0)),"")) | L18: =IF(OR(H18="",I18="支払い済み",B18=""),"",H18-TODAY())
A19: =IF(B19="","",ROW()-10) | D19: =IF(C19="","",IFERROR(INDEX('案件台帳'!$B$6:$B$105,MATCH(C19,'案件台帳'!$A$6:$A$105,0)),"")) | L19: =IF(OR(H19="",I19="支払い済み",B19=""),"",H19-TODAY())
A20: =IF(B20="","",ROW()-10) | D20: =IF(C20="","",IFERROR(INDEX('案件台帳'!$B$6:$B$105,MATCH(C20,'案件台帳'!$A$6:$A$105,0)),"")) | L20: =IF(OR(H20="",I20="支払い済み",B20=""),"",H20-TODAY())
A21: =IF(B21="","",ROW()-10) | D21: =IF(C21="","",IFERROR(INDEX('案件台帳'!$B$6:$B$105,MATCH(C21,'案件台帳'!$A$6:$A$105,0)),"")) | L21: =IF(OR(H21="",I21="支払い済み",B21=""),"",H21-TODAY())
A22: =IF(B22="","",ROW()-10) | D22: =IF(C22="","",IFERROR(INDEX('案件台帳'!$B$6:$B$105,MATCH(C22,'案件台帳'!$A$6:$A$105,0)),"")) | L22: =IF(OR(H22="",I22="支払い済み",B22=""),"",H22-TODAY())
A23: =IF(B23="","",ROW()-10) | D23: =IF(C23="","",IFERROR(INDEX('案件台帳'!$B$6:$B$105,MATCH(C23,'案件台帳'!$A$6:$A$105,0)),"")) | L23: =IF(OR(H23="",I23="支払い済み",B23=""),"",H23-TODAY())
A24: =IF(B24="","",ROW()-10) | D24: =IF(C24="","",IFERROR(INDEX('案件台帳'!$B$6:$B$105,MATCH(C24,'案件台帳'!$A$6:$A$105,0)),"")) | L24: =IF(OR(H24="",I24="支払い済み",B24=""),"",H24-TODAY())
A25: =IF(B25="","",ROW()-10) | D25: =IF(C25="","",IFERROR(INDEX('案件台帳'!$B$6:$B$105,MATCH(C25,'案件台帳'!$A$6:$A$105,0)),"")) | L25: =IF(OR(H25="",I25="支払い済み",B25=""),"",H25-TODAY())
A26: =IF(B26="","",ROW()-10) | D26: =IF(C26="","",IFERROR(INDEX('案件台帳'!$B$6:$B$105,MATCH(C26,'案件台帳'!$A$6:$A$105,0)),"")) | L26: =IF(OR(H26="",I26="支払い済み",B26=""),"",H26-TODAY())
A27: =IF(B27="","",ROW()-10) | D27: =IF(C27="","",IFERROR(INDEX('案件台帳'!$B$6:$B$105,MATCH(C27,'案件台帳'!$A$6:$A$105,0)),"")) | L27: =IF(OR(H27="",I27="支払い済み",B27=""),"",H27-TODAY())
... A210: =IF(B210="","",ROW()-10) | D210: =IF(C210="","",IFERROR(INDEX('案件台帳'!$B$6:$B$105,MATCH(C210,'案件台帳'!$A$6:$A$105,0)),"")) | L210: =IF(OR(H210="",I210="支払い済み",B210=""),"",H210-TODAY())

Sheet 入出金帳
A1: 入出金帳
A2: 繰越残高 | B2: ='設定'!$C$15
A3: 合計 | F3: 現在の残高 → | G3: =SUM(G6:G505) | H3: =SUM(H6:H505) | I3: ='設定'!$C$15+G3-H3
A5: 日付 | B5: 案件No | C5: 案件名 | D5: 科目 | E5: 相手先 | F5: 摘要 | G5: 入金（税込） | H5: 出金（税込） | I5: 残高
A6: 46280 | C6: =IF(B6="","",IFERROR(INDEX('案件台帳'!$B$6:$B$105,MATCH(B6,'案件台帳'!$A$6:$A$105,0)),"")) | D6: 事務所経費 | E6: サンプル不動産管理 | F6: 事務所家賃 | H6: 55000 | I6: =IF(COUNT(G6:H6)=0,"",$B$2+SUM(G$6:G6)-SUM(H$6:H6))
A7: 46295 | B7: 2609-03 | C7: =IF(B7="","",IFERROR(INDEX('案件台帳'!$B$6:$B$105,MATCH(B7,'案件台帳'!$A$6:$A$105,0)),"")) | D7: 請負代金入金 | E7: 個人（サンプル様） | F7: 屋根防水工事 代金 | G7: 1320000 | I7: =IF(COUNT(G7:H7)=0,"",$B$2+SUM(G$6:G7)-SUM(H$6:H7))
A8: 46296 | B8: 2610-01 | C8: =IF(B8="","",IFERROR(INDEX('案件台帳'!$B$6:$B$105,MATCH(B8,'案件台帳'!$A$6:$A$105,0)),"")) | D8: 請負代金入金 | E8: サンプル不動産株式会社 | F8: 外壁改修 着手金 | G8: 2000000 | I8: =IF(COUNT(G8:H8)=0,"",$B$2+SUM(G$6:G8)-SUM(H$6:H8))
A9: 46300 | C9: =IF(B9="","",IFERROR(INDEX('案件台帳'!$B$6:$B$105,MATCH(B9,'案件台帳'!$A$6:$A$105,0)),"")) | D9: 交通費（ETC・ガソリン） | E9: ETC | F9: 10月前半分 | H9: 12000 | I9: =IF(COUNT(G9:H9)=0,"",$B$2+SUM(G$6:G9)-SUM(H$6:H9))
A10: 46304 | B10: 2609-03 | C10: =IF(B10="","",IFERROR(INDEX('案件台帳'!$B$6:$B$105,MATCH(B10,'案件台帳'!$A$6:$A$105,0)),"")) | D10: 外注費 | E10: サンプル板金 | F10: 9月分 支払い | H10: 330000 | I10: =IF(COUNT(G10:H10)=0,"",$B$2+SUM(G$6:G10)-SUM(H$6:H10))
A11: 46307 | C11: =IF(B11="","",IFERROR(INDEX('案件台帳'!$B$6:$B$105,MATCH(B11,'案件台帳'!$A$6:$A$105,0)),"")) | D11: 消耗品 | E11: ホームセンター | F11: 養生材・工具 | H11: 8600 | I11: =IF(COUNT(G11:H11)=0,"",$B$2+SUM(G$6:G11)-SUM(H$6:H11))
C12: =IF(B12="","",IFERROR(INDEX('案件台帳'!$B$6:$B$105,MATCH(B12,'案件台帳'!$A$6:$A$105,0)),"")) | I12: =IF(COUNT(G12:H12)=0,"",$B$2+SUM(G$6:G12)-SUM(H$6:H12))
C13: =IF(B13="","",IFERROR(INDEX('案件台帳'!$B$6:$B$105,MATCH(B13,'案件台帳'!$A$6:$A$105,0)),"")) | I13: =IF(COUNT(G13:H13)=0,"",$B$2+SUM(G$6:G13)-SUM(H$6:H13))
C14: =IF(B14="","",IFERROR(INDEX('案件台帳'!$B$6:$B$105,MATCH(B14,'案件台帳'!$A$6:$A$105,0)),"")) | I14: =IF(COUNT(G14:H14)=0,"",$B$2+SUM(G$6:G14)-SUM(H$6:H14))
C15: =IF(B15="","",IFERROR(INDEX('案件台帳'!$B$6:$B$105,MATCH(B15,'案件台帳'!$A$6:$A$105,0)),"")) | I15: =IF(COUNT(G15:H15)=0,"",$B$2+SUM(G$6:G15)-SUM(H$6:H15))
C16: =IF(B16="","",IFERROR(INDEX('案件台帳'!$B$6:$B$105,MATCH(B16,'案件台帳'!$A$6:$A$105,0)),"")) | I16: =IF(COUNT(G16:H16)=0,"",$B$2+SUM(G$6:G16)-SUM(H$6:H16))
C17: =IF(B17="","",IFERROR(INDEX('案件台帳'!$B$6:$B$105,MATCH(B17,'案件台帳'!$A$6:$A$105,0)),"")) | I17: =IF(COUNT(G17:H17)=0,"",$B$2+SUM(G$6:G17)-SUM(H$6:H17))
C18: =IF(B18="","",IFERROR(INDEX('案件台帳'!$B$6:$B$105,MATCH(B18,'案件台帳'!$A$6:$A$105,0)),"")) | I18: =IF(COUNT(G18:H18)=0,"",$B$2+SUM(G$6:G18)-SUM(H$6:H18))
C19: =IF(B19="","",IFERROR(INDEX('案件台帳'!$B$6:$B$105,MATCH(B19,'案件台帳'!$A$6:$A$105,0)),"")) | I19: =IF(COUNT(G19:H19)=0,"",$B$2+SUM(G$6:G19)-SUM(H$6:H19))
C20: =IF(B20="","",IFERROR(INDEX('案件台帳'!$B$6:$B$105,MATCH(B20,'案件台帳'!$A$6:$A$105,0)),"")) | I20: =IF(COUNT(G20:H20)=0,"",$B$2+SUM(G$6:G20)-SUM(H$6:H20))
C21: =IF(B21="","",IFERROR(INDEX('案件台帳'!$B$6:$B$105,MATCH(B21,'案件台帳'!$A$6:$A$105,0)),"")) | I21: =IF(COUNT(G21:H21)=0,"",$B$2+SUM(G$6:G21)-SUM(H$6:H21))
C22: =IF(B22="","",IFERROR(INDEX('案件台帳'!$B$6:$B$105,MATCH(B22,'案件台帳'!$A$6:$A$105,0)),"")) | I22: =IF(COUNT(G22:H22)=0,"",$B$2+SUM(G$6:G22)-SUM(H$6:H22))
C23: =IF(B23="","",IFERROR(INDEX('案件台帳'!$B$6:$B$105,MATCH(B23,'案件台帳'!$A$6:$A$105,0)),"")) | I23: =IF(COUNT(G23:H23)=0,"",$B$2+SUM(G$6:G23)-SUM(H$6:H23))
... C505: =IF(B505="","",IFERROR(INDEX('案件台帳'!$B$6:$B$105,MATCH(B505,'案件台帳'!$A$6:$A$105,0)),"")) | I505: =IF(COUNT(G505:H505)=0,"",$B$2+SUM(G$6:G505)-SUM(H$6:H505))
